Workbook

Sheet dummy_data
A1: UKPRN | B1: Name | C1: Country | D1: Ofs_Tariff_1920 | E1: TEF_1819 | F1: Student numbers | G1: Total Expenditure
A2: 10007814 | B2: =_xlfn.XLOOKUP($A2, PUBLISHED_Provider_Spine_202208!$A$2:$A$620, PUBLISHED_Provider_Spine_202208!$C$2:$C$620) -> Cardiff University | C2: =_xlfn.XLOOKUP($A2, PUBLISHED_Provider_Spine_202208!$A$2:$A$620, PUBLISHED_Provider_Spine_202208!$F$2:$F$620) -> Wales | D2: #N/A | E2: =_xlfn.XLOOKUP($A2, PUBLISHED_Provider_Spine_202208!$A$2:$A$620, PUBLISHED_Provider_Spine_202208!$AG$2:$AG$620) -> Silver | F2: =_xlfn.XLOOKUP(A2, Students!$A$19:$A$300, Students!$G$19:$G$300) -> 33510 | G2: =_xlfn.XLOOKUP($A2, Finance!$A$18:$A$291, Finance!$P$18:$P$291) -> 573201
A3: 10007790 | B3: =_xlfn.XLOOKUP(A3, PUBLISHED_Provider_Spine_202208!$A$2:$A$620, PUBLISHED_Provider_Spine_202208!$C$2:$C$620) -> The University of Edinburgh | C3: =_xlfn.XLOOKUP($A3, PUBLISHED_Provider_Spine_202208!$A$2:$A$620, PUBLISHED_Provider_Spine_202208!$F$2:$F$620) -> Scotland | D3: #N/A | E3: =_xlfn.XLOOKUP($A3, PUBLISHED_Provider_Spine_202208!$A$2:$A$620, PUBLISHED_Provider_Spine_202208!$AG$2:$AG$620) -> No TEF | F3: =_xlfn.XLOOKUP(A3, Students!$A$19:$A$300, Students!$G$19:$G$300) -> 37830 | G3: =_xlfn.XLOOKUP($A3, Finance!$A$18:$A$291, Finance!$P$18:$P$291) -> 1060066
A4: 10007794 | B4: =_xlfn.XLOOKUP(A4, PUBLISHED_Provider_Spine_202208!$A$2:$A$620, PUBLISHED_Provider_Spine_202208!$C$2:$C$620) -> The University of Glasgow | C4: =_xlfn.XLOOKUP($A4, PUBLISHED_Provider_Spine_202208!$A$2:$A$620, PUBLISHED_Provider_Spine_202208!$F$2:$F$620) -> Scotland | D4: #N/A | E4: =_xlfn.XLOOKUP($A4, PUBLISHED_Provider_Spine_202208!$A$2:$A$620, PUBLISHED_Provider_Spine_202208!$AG$2:$AG$620) -> No TEF | F4: =_xlfn.XLOOKUP(A4, Students!$A$19:$A$300, Students!$G$19:$G$300) -> 37145 | G4: =_xlfn.XLOOKUP($A4, Finance!$A$18:$A$291, Finance!$P$18:$P$291) -> 695820
A5: 10000291 | B5: =_xlfn.XLOOKUP(A5, PUBLISHED_Provider_Spine_202208!$A$2:$A$620, PUBLISHED_Provider_Spine_202208!$C$2:$C$620) -> Anglia Ruskin University Higher Education Corporation | C5: =_xlfn.XLOOKUP($A5, PUBLISHED_Provider_Spine_202208!$A$2:$A$620, PUBLISHED_Provider_Spine_202208!$F$2:$F$620) -> England | D5: =_xlfn.XLOOKUP($A5, PUBLISHED_Provider_Spine_202208!$A$2:$A$620, PUBLISHED_Provider_Spine_202208!$AD$2:$AD$620) -> HEIs with low scores | E5: =_xlfn.XLOOKUP($A5, PUBLISHED_Provider_Spine_202208!$A$2:$A$620, PUBLISHED_Provider_Spine_202208!$AG$2:$AG$620) -> Silver | F5: =_xlfn.XLOOKUP(A5, Students!$A$19:$A$300, Students!$G$19:$G$300) -> 32180 | G5: =_xlfn.XLOOKUP($A5, Finance!$A$18:$A$291, Finance!$P$18:$P$291) -> 270231
A6: 10008640 | B6: =_xlfn.XLOOKUP(A6, PUBLISHED_Provider_Spine_202208!$A$2:$A$620, PUBLISHED_Provider_Spine_202208!$C$2:$C$620) -> Falmouth University | C6: =_xlfn.XLOOKUP($A6, PUBLISHED_Provider_Spine_202208!$A$2:$A$620, PUBLISHED_Provider_Spine_202208!$F$2:$F$620) -> England | D6: =_xlfn.XLOOKUP($A6, PUBLISHED_Provider_Spine_202208!$A$2:$A$620, PUBLISHED_Provider_Spine_202208!$AD$2:$AD$620) -> Specialist HEI | E6: =_xlfn.XLOOKUP($A6, PUBLISHED_Provider_Spine_202208!$A$2:$A$620, PUBLISHED_Provider_Spine_202208!$AG$2:$AG$620) -> Gold | F6: =_xlfn.XLOOKUP(A6, Students!$A$19:$A$300, Students!$G$19:$G$300) -> 6170 | G6: =_xlfn.XLOOKUP($A6, Finance!$A$18:$A$291, Finance!$P$18:$P$291) -> 64303
A7: 10007760 | B7: =_xlfn.XLOOKUP(A7, PUBLISHED_Provider_Spine_202208!$A$2:$A$620, PUBLISHED_Provider_Spine_202208!$C$2:$C$620) -> Birkbeck College | C7: =_xlfn.XLOOKUP($A7, PUBLISHED_Provider_Spine_202208!$A$2:$A$620, PUBLISHED_Provider_Spine_202208!$F$2:$F$620) -> England | D7: =_xlfn.XLOOKUP($A7, PUBLISHED_Provider_Spine_202208!$A$2:$A$620, PUBLISHED_Provider_Spine_202208!$AD$2:$AD$620) -> Specialist HEI | E7: =_xlfn.XLOOKUP($A7, PUBLISHED_Provider_Spine_202208!$A$2:$A$620, PUBLISHED_Provider_Spine_202208!$AG$2:$AG$620) -> Silver | F7: =_xlfn.XLOOKUP(A7, Students!$A$19:$A$300, Students!$G$19:$G$300) -> 12070 | G7: =_xlfn.XLOOKUP($A7, Finance!$A$18:$A$291, Finance!$P$18:$P$291) -> 106783
A8: 10007792 | B8: =_xlfn.XLOOKUP(A8, PUBLISHED_Provider_Spine_202208!$A$2:$A$620, PUBLISHED_Provider_Spine_202208!$C$2:$C$620) -> University of Exeter | C8: =_xlfn.XLOOKUP($A8, PUBLISHED_Provider_Spine_202208!$A$2:$A$620, PUBLISHED_Provider_Spine_202208!$F$2:$F$620) -> England | D8: =_xlfn.XLOOKUP($A8, PUBLISHED_Provider_Spine_202208!$A$2:$A$620, PUBLISHED_Provider_Spine_202208!$AD$2:$AD$620) -> HEIs with high scores | E8: =_xlfn.XLOOKUP($A8, PUBLISHED_Provider_Spine_202208!$A$2:$A$620, PUBLISHED_Provider_Spine_202208!$AG$2:$AG$620) -> Gold | F8: =_xlfn.XLOOKUP(A8, Students!$A$19:$A$300, Students!$G$19:$G$300) -> 30250 | G8: =_xlfn.XLOOKUP($A8, Finance!$A$18:$A$291, Finance!$P$18:$P$291) -> 512915
A9: 10007799 | B9: =_xlfn.XLOOKUP(A9, PUBLISHED_Provider_Spine_202208!$A$2:$A$620, PUBLISHED_Provider_Spine_202208!$C$2:$C$620) -> University of Newcastle upon Tyne | C9: =_xlfn.XLOOKUP($A9, PUBLISHED_Provider_Spine_202208!$A$2:$A$620, PUBLISHED_Provider_Spine_202208!$F$2:$F$620) -> England | D9: =_xlfn.XLOOKUP($A9, PUBLISHED_Provider_Spine_202208!$A$2:$A$620, PUBLISHED_Provider_Spine_202208!$AD$2:$AD$620) -> HEIs with high scores | E9: =_xlfn.XLOOKUP($A9, PUBLISHED_Provider_Spine_202208!$A$2:$A$620, PUBLISHED_Provider_Spine_202208!$AG$2:$AG$620) -> Gold | F9: =_xlfn.XLOOKUP(A9, Students!$A$19:$A$300, Students!$G$19:$G$300) -> 27775 | G9: =_xlfn.XLOOKUP($A9, Finance!$A$18:$A$291, Finance!$P$18:$P$291) -> 530603
A10: 10007154 | B10: =_xlfn.XLOOKUP(A10, PUBLISHED_Provider_Spine_202208!$A$2:$A$620, PUBLISHED_Provider_Spine_202208!$C$2:$C$620) -> University of Nottingham, the | C10: =_xlfn.XLOOKUP($A10, PUBLISHED_Provider_Spine_202208!$A$2:$A$620, PUBLISHED_Provider_Spine_202208!$F$2:$F$620) -> England | D10: =_xlfn.XLOOKUP($A10, PUBLISHED_Provider_Spine_202208!$A$2:$A$620, PUBLISHED_Provider_Spine_202208!$AD$2:$AD$620) -> HEIs with high scores | E10: =_xlfn.XLOOKUP($A10, PUBLISHED_Provider_Spine_202208!$A$2:$A$620, PUBLISHED_Provider_Spine_202208!$AG$2:$AG$620) -> Gold | F10: =_xlfn.XLOOKUP(A10, Students!$A$19:$A$300, Students!$G$19:$G$300) -> 35785 | G10: =_xlfn.XLOOKUP($A10, Finance!$A$18:$A$291, Finance!$P$18:$P$291) -> 683714

Sheet PUBLISHED_Provider_Spine_202208
A1: UKPRN | B1: INSTID | C1: Name | D1: Short_name | E1: UCAS_code | F1: Country | G1: Region | H1: Postcode | I1: Longitude | J1: Latitude | K1: LTLA_code | L1: LTLA_name | M1: ITL_code | N1: ITL_name | O1: Constituency | P1: Town_or_City | Q1: OfS_register | R1: HESA_FR | S1: HESA_Staff | T1: HESA_SR | U1: Grad_outcomes | V1: Unistats | W1: SLC | X1: UCAS | Y1: Prov_type | Z1: Old_Prov_type | AA1: Reg_cat | AB1: T_grant_2223 | AC1: HCSF_2223 | AD1: Ofs_Tariff_1920 | AE1: WP_UCAS_Tariff | AF1: TRAC_1819 | AG1: TEF_1819 | AH1: Mission_groups | AI1: New_in_update
A2: 10007849 | B2: 95 | C2: Abertay University | D2: Abertay | E2: A30 | F2: Scotland | G2: Scotland | H2: DD1 1HG | I2: -2.974299 | J2: 56.463117 | K2: S12000042 | L2: Dundee City | M2: S30000049 | N2: Dundee City | O2: Dundee West | P2: NA | Q2: 0 | R2: 1 | S2: 1 | T2: 1 | U2: 0 | V2: 0 | W2: 1 | X2: 1 | Y2: None | Z2: HEI | AA2: Not OfS | AB2: NA | AC2: NA | AD2: No tariff | AE2: High | AF2: C | AG2: Silver | AH2: MillionPlus, GuildHE | AI2: 0
A3: 10007856 | B3: 177 | C3: Aberystwyth University | D3: Aberystwyth | E3: A40 | F3: Wales | G3: Wales | H3: SY23 2AX | I3: -4.043584 | J3: 52.403464 | K3: W06000008 | L3: Ceredigion | M3: W06000008 | N3: Ceredigion | O3: Ceredigion | Q3: 0 | R3: 1 | S3: 1 | T3: 1 | U3: 0 | V3: 0 | W3: 1 | X3: 1 | Y3: None | Z3: HEI | AA3: Not OfS | AB3: NA | AC3: NA | AD3: No tariff | AE3: Low | AF3: B | AG3: Gold | AH3: None | AI3: 0
A4: 10019746 | B4: 231 | C4: ABI College Limited | D4: ABI | E4: Not UCAS | F4: England | G4: London | H4: W3 9NW | I4: -0.271846 | J4: 51.507759 | K4: E09000009 | L4: Ealing | M4: E09000009 | N4: Ealing | O4: Ealing Central and Acton | P4: London | Q4: 0 | R4: 0 | S4: 0 | T4: 0 | U4: 0 | V4: 0 | W4: 0 | X4: 0 | Y4: None | Z4: AP | AA4: Not OfS | AB4: NA | AC4: NA | AD4: No tariff | AE4: No WP Tariff | AF4: No TRAC | AG4: No TEF | AH4: None | AI4: Jun 2022 (other)
A5: 10000055 | B5: 1183 | C5: Abingdon and Witney College | D5: Abingdon College | E5: A14 | F5: England | G5: South East | H5: OX14 1GG | I5: -1.28696 | J5: 51.680624 | K5: E07000180 | L5: Vale of White Horse | M5: E07000180 | N5: Vale of White Horse | O5: Oxford West and Abingdon | Q5: 1 | R5: 0 | S5: 0 | T5: 0 | U5: 0 | V5: 0 | W5: 0 | X5: 1 | Y5: FEC | Z5: FEC | AA5: Approved (fee cap) | AB5: Yes | AC5: Yes | AD5: Further education and sixth form colleges | AE5: No WP Tariff | AF5: No TRAC | AG5: Silver | AH5: AoC | AI5: 0
A6: 10000248 | B6: 269 | C6: Academy of Live and Recorded Arts | D6: ALRA | E6: Not UCAS | F6: England | G6: London | H6: SW18 3SX | I6: -0.174557 | J6: 51.4533 | K6: E09000032 | L6: Wandsworth | M6: E09000032 | N6: Wandsworth | O6: Tooting | P6: London | Q6: 0 | R6: 0 | S6: 0 | T6: 1 | U6: 0 | V6: 0 | W6: 1 | X6: 0 | Y6: None | Z6: AP | AA6: Not OfS | AB6: NA | AC6: NA | AD6: No tariff | AE6: Medium | AF6: No TRAC | AG6: Silver | AH6: GuildHE | AI6: 0
A7: 10000080 | B7: 268 | C7: Access to Music Limited | D7: Access to Music | E7: Not UCAS | F7: England | G7: West Midlands | H7: B9 4AR | I7: -1.88286 | J7: 52.476431 | K7: E08000025 | L7: Birmingham | M7: E08000025 | N7: Birmingham | O7: Birmingham, Ladywood | P7: Birmingham | Q7: 0 | R7: 0 | S7: 0 | T7: 0 | U7: 0 | V7: 0 | W7: 0 | X7: 0 | Y7: None | Z7: AP | AA7: Not OfS | AB7: NA | AC7: NA | AD7: No tariff | AE7: No WP Tariff | AF7: No TRAC | AG7: No TEF | AH7: None | AI7: Jun 2022 (other)
A8: 10000093 | B8: 1182 | C8: Accrington and Rossendale College | D8: Accrington College | E8: Not UCAS | F8: England | G8: North West | H8: BB5 2AW | I8: -2.35286 | J8: 53.748697 | K8: E07000120 | L8: Hyndburn | M8: E07000120 | N8: Hyndburn | O8: Hyndburn | Q8: 0 | R8: 0 | S8: 0 | T8: 0 | U8: 0 | V8: 0 | W8: 0 | X8: 0 | Y8: None | Z8: Unknown | AA8: Not OfS | AB8: NA | AC8: NA | AD8: No tariff | AE8: No WP Tariff | AF8: No TRAC | AG8: No TEF | AH8: AoC | AI8: 0
A9: 10067853 | B9: 357 | C9: ACM Guildford Ltd | D9: ACM Guildford | E9: Not UCAS | F9: England | G9: South East | H9: GU1 4SB | I9: -0.578092 | J9: 51.236455 | K9: E07000209 | L9: Guildford | M9: E07000209 | N9: Guildford | O9: Guildford | P9: Guildford | Q9: 1 | R9: 0 | S9: 1 | T9: 1 | U9: 0 | V9: 0 | W9: 1 | X9: 0 | Y9: No university title | Z9: AP | AA9: Approved (fee cap) | AB9: Yes | AC9: Yes | AD9: Other providers | AE9: Low | AF9: No TRAC | AG9: Bronze | AH9: GuildHE | AI9: 0
A10: 10004927 | B10: 1181 | C10: Activate Learning | D10: Activate Learning | E10: O25 | F10: England | G10: South East | H10: OX1 1SA | I10: -1.264524 | J10: 51.749548 | K10: E07000178 | L10: Oxford | M10: E07000178 | N10: Oxford | O10: Oxford East | P10: Oxford | Q10: 1 | R10: 0 | S10: 0 | T10: 0 | U10: 0 | V10: 0 | W10: 1 | X10: 1 | Y10: FEC | Z10: FEC | AA10: Approved (fee cap) | AB10: Yes | AC10: Yes | AD10: Further education and sixth form colleges | AE10: No WP Tariff | AF10: No TRAC | AG10: Silver | AH10: AoC | AI10: 0
A11: 10000163 | B11: 213 | C11: AECC University College | D11: AECC | E11: A65 | F11: England | G11: South West | H11: BH5 2DF | I11: -1.828772 | J11: 50.727261 | K11: E06000058 | L11: Bournemouth, Christchurch and Poole | M11: E06000058 | N11: Bournemouth, Christchurch and Poole | O11: Bournemouth East | P11: Bournemouth | Q11: 1 | R11: 0 | S11: 1 | T11: 1 | U11: 0 | V11: 0 | W11: 1 | X11: 1 | Y11: University Title | Z11: HEI | AA11: Approved (fee cap) | AB11: Yes | AC11: Yes | AD11: Other providers | AE11: Medium | AF11: E | AG11: Silver | AH11: GuildHE | AI11: 0
A12: 10000216 | B12: 285 | C12: All Nations Christian College Limited | D12: All Nations | E12: Not UCAS | F12: England | G12: East of England | H12: SG12 8LX | I12: 0.000933 | J12: 51.80252 | K12: E07000242 | L12: East Hertfordshire | M12: E07000242 | N12: East Hertfordshire | O12: Hertford and Stortford | Q12: 1 | R12: 0 | S12: 0 | T12: 1 | U12: 0 | V12: 0 | W12: 0 | X12: 0 | Y12: No university title | Z12: AP | AA12: Approved | AB12: No | AC12: No | AD12: No tariff | AE12: c | AF12: No TRAC | AG12: No TEF | AH12: None | AI12: 0
A13: 10032036 | B13: 353 | C13: Amity Global Education Ltd | D13: Amity | E13: A11 | F13: England | G13: London | H13: WC1B 3HN | I13: -0.131146 | J13: 51.519206 | K13: E09000007 | L13: Camden | M13: E09000007 | N13: Camden | O13: Holborn and St Pancras | P13: London | Q13: 1 | R13: 0 | S13: 1 | T13: 1 | U13: 0 | V13: 0 | W13: 1 | X13: 1 | Y13: University Title | Z13: AP | AA13: Approved (fee cap) | AB13: Yes | AC13: No | AD13: Other providers | AE13: No WP Tariff | AF13: No TRAC | AG13: Provisional | AH13: None | AI13: 0
A14: UCAS: no UKPRN | B14: No INSTID | C14: Amsterdam Fashion Academy | D14: Amsterdam Fashion | E14: A57 | F14: NA | G14: NA | H14: NA | I14: 4.901927 | J14: 52.359848 | K14: International | L14: International | M14: International | N14: International | O14: International | P14: NA | Q14: 0 | R14: 0 | S14: 0 | T14: 0 | U14: 0 | V14: 0 | W14: 0 | X14: 1 | Y14: None | Z14: Unknown | AA14: Not OfS | AB14: NA | AC14: NA | AD14: No tariff | AE14: No WP Tariff | AF14: No TRAC | AG14: No TEF | AH14: None | AI14: 0
A15: 10000291 | B15: 47 | C15: Anglia Ruskin University Higher Education Corporation | D15: Anglia Ruskin | E15: A60 | F15: England | G15: East of England | H15: CM1 1SQ | I15: 0.474495 | J15: 51.741381 | K15: E07000070 | L15: Chelmsford | M15: E07000070 | N15: Chelmsford | O15: Chelmsford | P15: Chelmsford | Q15: 1 | R15: 0 | S15: 1 | T15: 1 | U15: 0 | V15: 0 | W15: 1 | X15: 1 | Y15: University Title | Z15: HEI | AA15: Approved (fee cap) | AB15: Yes | AC15: Yes | AD15: HEIs with low scores | AE15: Low | AF15: D | AG15: Silver | AH15: University Alliance | AI15: 0
A16: 10062759 | B16: 432 | C16: Applied Business Academy Limited | D16: Applied Business Academy | E16: Not UCAS | F16: England | G16: London | H16: E14 9RH | I16: -0.014275 | J16: 51.49744 | K16: E09000030 | L16: Tower Hamlets | M16: E09000030 | N16: Tower Hamlets | O16: Poplar and Limehouse | P16: London | Q16: 1 | R16: 0 | S16: 0 | T16: 1 | U16: 0 | V16: 0 | W16: 1 | X16: 0 | Y16: No university title | Z16: Unknown | AA16: Approved | AB16: No | AC16: No | AD16: No tariff | AE16: No WP Tariff | AF16: No TRAC | AG16: No TEF | AH16: None | AI16: Jan 2021 (OfS register)
A17: 10008071 | B17: 323 | C17: Architectural Association (Incorporated) | D17: Architectural Association | E17: Not UCAS | F17: England | G17: London | H17: WC1B 3ES | I17: -0.130697 | J17: 51.518218 | K17: E09000007 | L17: Camden | M17: E09000007 | N17: Camden | O17: Holborn and St Pancras | P17: London | Q17: 1 | R17: 0 | S17: 0 | T17: 1 | U17: 0 | V17: 0 | W17: 0 | X17: 0 | Y17: No university title | Z17: AP | AA17: Approved | AB17: No | AC17: No | AD17: No tariff | AE17: c | AF17: No TRAC | AG17: No TEF | AH17: None | AI17: 0
A18: 10005451 | B18: 333 | C18: Arden University Limited | D18: Arden Uni | E18: R25 | F18: England | G18: West Midlands | H18: CV3 4FJ | I18: -1.466384 | J18: 52.373008 | K18: E07000222 | L18: Warwick | M18: E07000222 | N18: Warwick | O18: Kenilworth and Southam | Q18: 1 | R18: 0 | S18: 1 | T18: 1 | U18: 0 | V18: 0 | W18: 1 | X18: 1 | Y18: University Title | Z18: AP | AA18: Approved (fee cap) | AB18: Yes | AC18: Yes | AD18: Other providers | AE18: Low | AF18: No TRAC | AG18: Provisional | AH18: None | AI18: 0
A19: 10044534 | B19: No INSTID | C19: Ark Teacher Training | D19: Ark Teacher Training | E19: Not UCAS | F19: England | G19: London | H19: WC2B 6TD | I19: -0.119475 | J19: 51.515334 | K19: E09000007 | L19: Camden | M19: E09000007 | N19: Camden | O19: Holborn and St Pancras | P19: London | Q19: 0 | R19: 0 | S19: 0 | T19: 0 | U19: 0 | V19: 0 | W19: 1 | X19: 0 | Y19: None | Z19: SCITT | AA19: Not OfS | AB19: NA | AC19: NA | AD19: No tariff | AE19: No WP Tariff | AF19: No TRAC | AG19: No TEF | AH19: None | AI19: Apr 2021 (SLC)
A20: 10034759 | B20: No INSTID | C20: Arthur Terry National Teaching School Alliance | D20: Arthur Terry | E20: Not UCAS | F20: England | G20: West Midlands | H20: B74 4RZ | I20: -1.836208 | J20: 52.589596 | K20: E08000025 | L20: Birmingham | M20: E08000025 | N20: Birmingham | O20: Sutton Coldfield | P20: Sutton Coldfield | Q20: 0 | R20: 0 | S20: 0 | T20: 0 | U20: 0 | V20: 0 | W20: 1 | X20: 0 | Y20: None | Z20: Unknown | AA20: Not OfS | AB20: NA | AC20: NA | AD20: No tariff | AE20: No WP Tariff | AF20: No TRAC | AG20: No TEF | AH20: None | AI20: Apr 2021 (SLC)
A21: 10000381 | B21: 244 | C21: Arts Educational Schools(The) | D21: Arts Educational Schools | E21: Not UCAS | F21: England | G21: London | H21: W4 1LY | I21: -0.252435 | J21: 51.49596 | K21: E09000018 | L21: Hounslow | M21: E09000018 | N21: Hounslow | O21: Brentford and Isleworth | P21: London | Q21: 1 | R21: 0 | S21: 0 | T21: 1 | U21: 0 | V21: 0 | W21: 1 | X21: 0 | Y21: No university title | Z21: AP | AA21: Approved | AB21: No | AC21: No | AD21: No tariff | AE21: Medium | AF21: No TRAC | AG21: Gold | AH21: None | AI21: 0
A22: 10000385 | B22: 197 | C22: Arts University Bournemouth | D22: Arts Bournemouth | E22: A66 | F22: England | G22: South West | H22: BH12 5HH | I22: -1.897728 | J22: 50.741808 | K22: E06000058 | L22: Bournemouth, Christchurch and Poole | M22: E06000058 | N22: Bournemouth, Christchurch and Poole | O22: Bournemouth West | P22: Poole | Q22: 1 | R22: 0 | S22: 1 | T22: 1 | U22: 0 | V22: 0 | W22: 1 | X22: 1 | Y22: University Title | Z22: HEI | AA22: Approved (fee cap) | AB22: Yes | AC22: Yes | AD22: Specialist HEI | AE22: Medium | AF22: F | AG22: Gold | AH22: GuildHE | AI22: 0
A23: 10005127 | B23: 230 | C23: Arts University Plymouth | D23: Plymouth Art | E23: P65 | F23: England | G23: South West | H23: PL4 8AT | I23: -4.137411 | J23: 50.37341 | K23: E06000026 | L23: Plymouth | M23: E06000026 | N23: Plymouth | O23: Plymouth, Sutton and Devonport | P23: Plymouth | Q23: 1 | R23: 0 | S23: 1 | T23: 1 | U23: 0 | V23: 0 | W23: 1 | X23: 1 | Y23: University Title | Z23: HEI | AA23: Approved (fee cap) | AB23: Yes | AC23: Yes | AD23: Specialist HEI | AE23: Medium | AF23: F | AG23: Bronze | AH23: GuildHE | AI23: 0
A24: 10004011 | B24: No INSTID | C24: ARU London | D24: ARU London | E24: L63 | F24: England | G24: London | H24: EC1N 6RA | I24: -0.106332 | J24: 51.518423 | K24: E09000007 | L24: Camden | M24: E09000007 | N24: Camden | O24: Holborn and St Pancras | P24: London | Q24: 0 | R24: 0 | S24: 0 | T24: 0 | U24: 0 | V24: 0 | W24: 0 | X24: 1 | Y24: None | Z24: Unknown | AA24: Not OfS | AB24: NA | AC24: NA | AD24: No tariff | AE24: No WP Tariff | AF24: No TRAC | AG24: No TEF | AH24: None | AI24: 0
A25: 10000415 | B25: 1179 | C25: Askham Bryan College | D25: Askham Bryan College | E25: A70 | F25: England | G25: Yorkshire and The Humber | H25: YO23 3FR | I25: -1.161491 | J25: 53.920657 | K25: E06000014 | L25: York | M25: E06000014 | N25: York | O25: York Outer | Q25: 1 | R25: 0 | S25: 0 | T25: 0 | U25: 0 | V25: 0 | W25: 1 | X25: 1 | Y25: FEC | Z25: FEC | AA25: Approved (fee cap) | AB25: Yes | AC25: Yes | AD25: Further education and sixth form colleges | AE25: No WP Tariff | AF25: No TRAC | AG25: Bronze | AH25: AoC | AI25: 0
A26: 10020416 | B26: 225 | C26: Assemblies of God Incorporated | D26: Assemblies of God | E26: Not UCAS | F26: England | G26: North West | H26: M3 7BE | I26: -2.253974 | J26: 53.484297 | K26: E08000006 | L26: Salford | M26: E08000006 | N26: Salford | O26: Salford and Eccles | P26: Salford | Q26: 1 | R26: 0 | S26: 0 | T26: 1 | U26: 0 | V26: 0 | W26: 0 | X26: 0 | Y26: No university title | Z26: AP | AA26: Approved | AB26: No | AC26: No | AD26: No tariff | AE26: c | AF26: No TRAC | AG26: Bronze | AH26: None | AI26: 0
A27: 10055360 | B27: No INSTID | C27: Associated Merseyside Partnership Scitt | D27: Associated Merseyside Scitt | E27: Not UCAS | F27: England | G27: North West | H27: L31 1EP | I27: -2.92347 | J27: 53.495613 | K27: E08000014 | L27: Sefton | M27: E08000014 | N27: Sefton | O27: Sefton Central | Q27: 0 | R27: 0 | S27: 0 | T27: 0 | U27: 0 | V27: 0 | W27: 1 | X27: 0 | Y27: None | Z27: SCITT | AA27: Not OfS | AB27: NA | AC27: NA | AD27: No tariff | AE27: No WP Tariff | AF27: No TRAC | AG27: No TEF | AH27: None | AI27: Apr 2021 (SLC)
A28: 10007759 | B28: 108 | C28: Aston University | D28: Aston | E28: A80 | F28: England | G28: West Midlands | H28: B4 7ET | I28: -1.890952 | J28: 52.486637 | K28: E08000025 | L28: Birmingham | M28: E08000025 | N28: Birmingham | O28: Birmingham, Ladywood | P28: Birmingham | Q28: 1 | R28: 0 | S28: 1 | T28: 1 | U28: 0 | V28: 0 | W28: 1 | X28: 1 | Y28: University Title | Z28: HEI | AA28: Approved (fee cap) | AB28: Yes | AC28: Yes | AD28: HEIs with high scores | AE28: Medium | AF28: B | AG28: Gold | AH28: None | AI28: 0
A29: 10000473 | B29: 1178 | C29: Aylesbury College | D29: Aylesbury College | E29: Not UCAS | F29: England | G29: South East | H29: HP21 8PD | I29: -0.822655 | J29: 51.813857 | K29: E06000060 | L29: Buckinghamshire | M29: E06000060 | N29: Buckinghamshire | O29: Aylesbury | Q29: 1 | R29: 0 | S29: 0 | T29: 0 | U29: 0 | V29: 0 | W29: 0 | X29: 0 | Y29: FEC | Z29: FEC | AA29: Approved (fee cap) | AB29: Yes | AC29: No | AD29: Further education and sixth form colleges | AE29: No WP Tariff | AF29: No TRAC | AG29: No TEF | AH29: None | AI29: 0
A30: 10036456 | B30: 426 | C30: Backstage Academy (Training) Ltd | D30: Backstage Academy | E30: Not UCAS | F30: England | G30: Yorkshire and The Humber | H30: WF9 3AP | I30: -1.309879 | J30: 53.589945 | K30: E08000036 | L30: Wakefield | M30: E08000036 | N30: Wakefield | O30: Hemsworth | Q30: 1 | R30: 0 | S30: 1 | T30: 1 | U30: 0 | V30: 0 | W30: 0 | X30: 0 | Y30: No university title | Z30: Unknown | AA30: Approved (fee cap) | AB30: Yes | AC30: Yes | AD30: Other providers | AE30: No WP Tariff | AF30: No TRAC | AG30: No TEF | AH30: None | AI30: 0
A31: 10042364 | B31: 324 | C31: Ballet West | D31: Ballet West | E31: Not UCAS | F31: Scotland | G31: Scotland | H31: PA35 1HP | I31: -5.226522 | J31: 56.426118 | K31: S12000035 | L31: Argyll and Bute | M31: S30000036 | N31: Argyll and Bute Mainland | O31: Argyll and Bute | P31: NA | Q31: 0 | R31: 0 | S31: 0 | T31: 0 | U31: 0 | V31: 0 | W31: 0 | X31: 0 | Y31: None | Z31: AP | AA31: Not OfS | AB31: NA | AC31: NA | AD31: No tariff | AE31: c | AF31: No TRAC | AG31: No TEF | AH31: None | AI31: 0
A32: 10007857 | B32: 178 | C32: Bangor University | D32: Bangor | E32: B06 | F32: Wales | G32: Wales | H32: LL57 2DG | I32: -4.129437 | J32: 53.229193 | K32: W06000002 | L32: Gwynedd | M32: W06000002 | N32: Gwynedd | O32: Arfon | Q32: 0 | R32: 1 | S32: 1 | T32: 1 | U32: 0 | V32: 0 | W32: 1 | X32: 1 | Y32: None | Z32: HEI | AA32: Not OfS | AB32: NA | AC32: NA | AD32: No tariff | AE32: Medium | AF32: B | AG32: Gold | AH32: None | AI32: 0
A33: 10000528 | B33: 1177 | C33: Barking and Dagenham College | D33: Barking College | E33: B11 | F33: England | G33: London | H33: RM7 0XU | I33: 0.174564 | J33: 51.56033 | K33: E09000002 | L33: Barking and Dagenham | M33: E09000002 | N33: Barking and Dagenham | O33: Dagenham and Rainham | P33: London | Q33: 0 | R33: 0 | S33: 0 | T33: 0 | U33: 0 | V33: 0 | W33: 0 | X33: 1 | Y33: FEC | Z33: FEC | AA33: Not OfS | AB33: NA | AC33: NA | AD33: No tariff | AE33: No WP Tariff | AF33: No TRAC | AG33: No TEF | AH33: AoC | AI33: 0
A34: 10000533 | B34: 1174 | C34: Barnet & Southgate College | D34: Barnet College | E34: B08 | F34: England | G34: London | H34: EN5 4AZ | I34: -0.2003 | J34: 51.652379 | K34: E09000003 | L34: Barnet | M34: E09000003 | N34: Barnet | O34: Chipping Barnet | P34: London | Q34: 1 | R34: 0 | S34: 0 | T34: 0 | U34: 0 | V34: 0 | W34: 1 | X34: 1 | Y34: FEC | Z34: FEC | AA34: Approved (fee cap) | AB34: Yes | AC34: Yes | AD34: Further education and sixth form colleges | AE34: No WP Tariff | AF34: No TRAC | AG34: Bronze | AH34: AoC | AI34: 0
A35: 10000534 | B35: 1176 | C35: Barnfield College | D35: Barnfield College | E35: B09 | F35: England | G35: East of England | H35: LU2 7BF | I35: -0.421883 | J35: 51.90603 | K35: E06000032 | L35: Luton | M35: E06000032 | N35: Luton | O35: Luton North | P35: Luton | Q35: 0 | R35: 0 | S35: 0 | T35: 0 | U35: 0 | V35: 0 | W35: 0 | X35: 1 | Y35: None | Z35: Unknown | AA35: Not OfS | AB35: NA | AC35: NA | AD35: No tariff | AE35: No WP Tariff | AF35: No TRAC | AG35: No TEF | AH35: AoC | AI35: 0
A36: 10000536 | B36: 1175 | C36: Barnsley College | D36: Barnsley College | E36: B13 | F36: England | G36: Yorkshire and The Humber | H36: S70 2AX | I36: -1.482572 | J36: 53.556624 | K36: E08000016 | L36: Barnsley | M36: E08000016 | N36: Barnsley | O36: Barnsley Central | P36: Barnsley | Q36: 1 | R36: 0 | S36: 0 | T36: 0 | U36: 0 | V36: 0 | W36: 1 | X36: 1 | Y36: FEC | Z36: FEC | AA36: Approved (fee cap) | AB36: Yes | AC36: Yes | AD36: Further education and sixth form colleges | AE36: No WP Tariff | AF36: No TRAC | AG36: Provisional | AH36: AoC | AI36: 0
A37: 10000560 | B37: 1173 | C37: Basingstoke College of Technology | D37: Basingstoke College | E37: Not UCAS | F37: England | G37: South East | H37: RG21 8TN | I37: -1.095958 | J37: 51.26336 | K37: E07000084 | L37: Basingstoke and Deane | M37: E07000084 | N37: Basingstoke and Deane | O37: Basingstoke | P37: Basingstoke | Q37: 1 | R37: 0 | S37: 0 | T37: 0 | U37: 0 | V37: 0 | W37: 0 | X37: 0 | Y37: FEC | Z37: FEC | AA37: Approved (fee cap) | AB37: Yes | AC37: Yes | AD37: Further education and sixth form colleges | AE37: No WP Tariff | AF37: No TRAC | AG37: No TEF | AH37: AoC | AI37: 0
A38: 10001465 | B38: 1172 | C38: Bath College | D38: Bath College | E38: B21 | F38: England | G38: South West | H38: BA1 1UP | I38: -2.362652 | J38: 51.379717 | K38: E06000022 | L38: Bath and North East Somerset | M38: E06000022 | N38: Bath and North East Somerset | O38: Bath | P38: Bath | Q38: 1 | R38: 0 | S38: 0 | T38: 0 | U38: 0 | V38: 0 | W38: 1 | X38: 1 | Y38: FEC | Z38: FEC | AA38: Approved (fee cap) | AB38: Yes | AC38: Yes | AD38: Further education and sixth form colleges | AE38: No WP Tariff | AF38: No TRAC | AG38: Silver | AH38: AoC | AI38: 0
A39: 10000571 | B39: 48 | C39: Bath Spa University | D39: Bath Spa | E39: B20 | F39: England | G39: South West | H39: BA2 9BN | I39: -2.440912 | J39: 51.373209 | K39: E06000022 | L39: Bath and North East Somerset | M39: E06000022 | N39: Bath and North East Somerset | O39: North East Somerset | Q39: 1 | R39: 0 | S39: 1 | T39: 1 | U39: 0 | V39: 0 | W39: 1 | X39: 1 | Y39: University Title | Z39: HEI | AA39: Approved (fee cap) | AB39: Yes | AC39: Yes | AD39: HEIs with medium scores | AE39: Low | AF39: E | AG39: Silver | AH39: MillionPlus, GuildHE | AI39: 0
A40: 10000911 | B40: 400 | C40: BCNO Limited | D40: BCNO | E40: B81 | F40: England | G40: London | H40: NW3 5RR | I40: -0.179372 | J40: 51.547841 | K40: E09000007 | L40: Camden | M40: E09000007 | N40: Camden | O40: Hampstead and Kilburn | P40: London | Q40: 1 | R40: 0 | S40: 0 | T40: 1 | U40: 0 | V40: 0 | W40: 0 | X40: 1 | Y40: No university title | Z40: Unknown | AA40: Approved | AB40: No | AC40: No | AD40: No tariff | AE40: No WP Tariff | AF40: No TRAC | AG40: No TEF | AH40: None | AI40: 0
...

Sheet Finance
A1: ﻿Title: | B1: Table 1 - Consolidated statement of comprehensive income and expenditure
A2: Subtitle: | B2: Academic years 2015/16 to 2020/21
A3: Reference ID: | B3: DT031 Table 1
A4: Data source: | B4: HESA / OfS
A5: Data source link: | B5: https://www.hesa.ac.uk/data-and-analysis/finances/table-1
A6: Data file canonical link: | B6: https://www.hesa.ac.uk/data-and-analysis/finances/table-1.csv
A7: Licence: | B7: Creative Commons Attribution 4.0 International Licence
A8: Date: | B8: 2022
A9: Filters: | B9: Country of HE provider | C9: All
B10: Region of HE provider | C10: All
B11: Academic year | C11: 2020/21
B12: Financial Year End | C12: All
A13: Search:
C16: Income (£000s) | D16: Expenditure (£000s)
A17: UKPRN | B17: HE Provider | C17: Financial Year End | D17: Tuition fees and education contracts | E17: Funding body grants | F17: Research grants and contracts | G17: Other income | H17: Investment income | I17: Donations and endowments | J17: Total income | K17: Staff costs | L17: Restructuring costs | M17: Other operating expenses | N17: Depreciation and amortisation | O17: Interest and other finance costs | P17: Total expenditure
A18: 10008071 | B18: AA School of Architecture | C18: 44408 | D18: 19072 | E18: 0 | F18: 0 | G18: 1332 | H18: 2 | I18: 870 | J18: 21276 | K18: 9574 | L18: 0 | M18: 6846 | N18: 393 | O18: 57 | P18: 16870
A19: 10007783 | B19: The University of Aberdeen | C19: 44408 | D19: 74423 | E19: 87577 | F19: 45927 | G19: 25764 | H19: 2012 | I19: 236 | J19: 235939 | K19: 146956 | L19: 0 | M19: 59306 | N19: 16855 | O19: 5840 | P19: 228957
A20: 10007849 | B20: Abertay University | C20: 44408 | D20: 10414 | E20: 21581 | F20: 2862 | G20: 2003 | H20: 313 | I20: 4 | J20: 37177 | K20: 27715 | L20: 0 | M20: 7300 | N20: 2671 | O20: 416 | P20: 38102
A21: 10007856 | B21: Aberystwyth University | C21: 44408 | D21: 53989 | E21: 22054 | F21: 20217 | G21: 21707 | H21: 233 | I21: 642 | J21: 118842 | K21: 66187 | L21: 184 | M21: 38544 | N21: 11946 | O21: 4003 | P21: 120864
A22: 10067853 | B22: ACM Guildford Limited | C22: 44074 | D22: 10614 | E22: 1381 | F22: 0 | G22: 619 | H22: 0 | I22: 0 | J22: 12614 | K22: 5953 | L22: 0 | M22: 3559 | N22: 101 | O22: 18 | P22: 9631
A23: 10000248 | B23: Academy of Live and Recorded Arts | C23: 44074 | D23: 2851 | E23: 0 | F23: 0 | G23: 283 | H23: 32 | I23: 0 | J23: 3166 | K23: 1507 | L23: 0 | M23: 1541 | N23: 85 | O23: 0 | P23: 3133
A24: 10000163 | B24: AECC University College | C24: 44408 | D24: 8064 | E24: 908 | F24: 32 | G24: 1390 | H24: 3 | I24: 38 | J24: 10435 | K24: 6159 | L24: 33 | M24: 2496 | N24: 509 | O24: 90 | P24: 9287
A25: 10032036 | B25: Amity Global Education | C25: 44286 | D25: 462 | E25: 26 | F25: 0 | G25: 644 | H25: 0 | I25: 0 | J25: 1132 | K25: 434 | L25: 0 | M25: 642 | N25: 1 | O25: 0 | P25: 1077
A26: 10000291 | B26: Anglia Ruskin University | C26: 44408 | D26: 230557 | E26: 23071 | F26: 3691 | G26: 11329 | H26: 9 | I26: 217 | J26: 268874 | K26: 109368 | L26: 0 | M26: 142863 | N26: 13279 | O26: 4721 | P26: 270231
A27: 10041898 | B27: Apex College London | C27: 44196 | D27: 642 | E27: 0 | F27: 0 | G27: 0 | H27: 0 | I27: 0 | J27: 642 | K27: 337 | L27: 0 | M27: 265 | N27: 0 | O27: 0 | P27: 602
A28: 10062759 | B28: Applied Business Academy Limited | C28: 44196 | D28: 321 | E28: 0 | F28: 0 | G28: 462 | H28: 0 | I28: 0 | J28: 783 | K28: 469 | L28: 0 | M28: 185 | N28: 32 | O28: 0 | P28: 686
A29: 10005451 | B29: Arden University | C29: 44135 | D29: 33272 | E29: 1985 | F29: 0 | G29: 1023 | H29: 564 | I29: 0 | J29: 36844 | K29: 16794 | L29: 0 | M29: 17646 | N29: 1142 | O29: 0 | P29: 35582
... A291: 10007167 | B291: The University of York | C291: 44408 | D291: 229082 | E291: 47471 | F291: 69810 | G291: 63351 | H291: 908 | I291: 3230 | J291: 413852 | K291: 246124 | L291: 0 | M291: 133947 | N291: 32334 | O291: 10276 | P291: 422681
B292: Year to date total | D292: 23462674 | E292: 6005301 | F292: 6561033 | G292: 6827826 | H292: 330833 | I292: 834262 | J292: 44021929 | K292: 23630712 | L292: 99592 | M292: 14890666 | N292: 2963640 | O292: 794166 | P292: 42378776

Sheet Students
A1: ﻿Title: | B1: Table 1 - HE student enrolments by HE provider
A2: Subtitle: | B2: Academic years 2014/15 to 2020/21
A3: Reference ID: | B3: DT051 Table 1
A4: Data source: | B4: HESA
A5: Data source link: | B5: https://www.hesa.ac.uk/data-and-analysis/students/table-1
A6: Data file canonical link: | B6: https://www.hesa.ac.uk/data-and-analysis/students/table-1.csv
A7: Licence: | B7: Creative Commons Attribution 4.0 International Licence
A8: Date: | B8: 2022
A9: Filters: | B9: Country of HE provider | C9: All
B10: Region of HE provider | C10: All
B11: First year marker | C11: All
B12: Level of study | C12: All
B13: Mode of study | C13: All
B14: Academic year | C14: 2020/21
A15: Search:
A18: UKPRN | B18: HE provider | C18: Female | D18: Male | E18: Other | F18: Not known | G18: Total
A19: 10008071 | B19: AA School of Architecture | C19: 575 | D19: 390 | E19: 0 | F19: 0 | G19: 965
A20: 10007783 | B20: The University of Aberdeen | C20: 9300 | D20: 6750 | E20: 30 | F20: 0 | G20: 16080
A21: 10007849 | B21: Abertay University | C21: 2180 | D21: 2385 | E21: 10 | F21: 0 | G21: 4575
A22: 10007856 | B22: Aberystwyth University | C22: 4385 | D22: 3535 | E22: 120 | F22: 0 | G22: 8040
A23: 10067853 | B23: ACM Guildford Limited | C23: 375 | D23: 790 | E23: 20 | F23: 0 | G23: 1185
A24: 10000248 | B24: Academy of Live and Recorded Arts | C24: 145 | D24: 125 | E24: 0 | F24: 0 | G24: 270
A25: 10000163 | B25: AECC University College | C25: 400 | D25: 475 | E25: 0 | F25: 0 | G25: 875
A26: 10032036 | B26: Amity Global Education | C26: 40 | D26: 40 | E26: 0 | F26: 0 | G26: 80
A27: 10000291 | B27: Anglia Ruskin University | C27: 20010 | D27: 12150 | E27: 20 | F27: 0 | G27: 32180
A28: 10041898 | B28: Apex College London | C28: 125 | D28: 45 | E28: 0 | F28: 0 | G28: 170
A29: 10062759 | B29: Applied Business Academy Limited | C29: 80 | D29: 140 | E29: 0 | F29: 0 | G29: 220
A30: 10005451 | B30: Arden University | C30: 7340 | D30: 4420 | E30: 0 | F30: 0 | G30: 11760
... A300: 10007167 | B300: The University of York | C300: 12615 | D300: 10050 | E300: 30 | F300: 0 | G300: 22695
B301: Total | C301: 1568795 | D301: 1177525 | E301: 5505 | F301: 35 | G301: 2751865
